<?xml version="1.0"?>
<robot name="pi_car" xmlns:xacro="http://ros.org/wiki/xacro">

  <xacro:property name="base_length" value="0.14"/> 
  <xacro:property name="base_width"  value="0.18"/> 
  <xacro:property name="base_height" value="0.09"/> 

  <xacro:property name="wheel_radius" value="0.0325"/> 
  <xacro:property name="wheel_width"  value="0.02"/>
  <xacro:property name="wheel_off_z"  value="-0.02"/> 
  
  <xacro:property name="wheel_off_x"  value="0.045"/> 

  <xacro:property name="lidar_radius" value="0.035"/>
  <xacro:property name="lidar_height" value="0.03"/>
  <xacro:property name="lidar_off_x"  value="0.0"/>   
  
  <xacro:property name="standoff_height" value="0.085"/> 

  <material name="blue"> <color rgba="0 0 0.8 1"/> </material>
  <material name="black"> <color rgba="0 0 0 1"/> </material>
  <material name="white"> <color rgba="1 1 1 1"/> </material>
  <material name="gold"> <color rgba="1 0.84 0 1"/> </material>

  <link name="base_footprint"/>

  <joint name="base_joint" type="fixed">
    <parent link="base_footprint"/>
    <child link="base_link"/>
    <origin xyz="0 0 50" rpy="0 0 0"/>
  </joint>

  <link name="base_link">
    <visual>
      <origin xyz="0 0 0.06" rpy="0 0 0"/>
      <geometry>
        <box size="${base_length} ${base_width} ${base_height}"/>
      </geometry>
      <material name="blue"/>
    </visual>
    <collision>
      <origin xyz="0 0 0" rpy="0 0 0"/>
      <geometry>
        <box size="${base_length} ${base_width} ${base_height}"/>
      </geometry>
    </collision>
  </link>

  <xacro:macro name="wheel" params="prefix reflect_y x_offset">
    <link name="${prefix}_wheel_link">
      <visual>
        <origin xyz="0 0 0.06" rpy="${pi/2} 0 0"/>
        <geometry>
          <cylinder radius="${wheel_radius}" length="${wheel_width}"/>
        </geometry>
        <material name="black"/>
      </visual>
      <collision>
        <origin xyz="0 0 0" rpy="${pi/2} 0 0"/>
        <geometry>
          <cylinder radius="${wheel_radius}" length="${wheel_width}"/>
        </geometry>
      </collision>
    </link>

    <joint name="${prefix}_wheel_joint" type="continuous">
      <parent link="base_link"/>
      <child link="${prefix}_wheel_link"/>
      <origin xyz="${x_offset} ${reflect_y*(base_width/2 + wheel_width/2)} ${wheel_off_z}" rpy="0 0 0"/>
      <axis xyz="0 1 0"/>
    </joint>
  </xacro:macro>

  <xacro:wheel prefix="front_left"  reflect_y="1"  x_offset="${wheel_off_x}"/>
  <xacro:wheel prefix="front_right" reflect_y="-1" x_offset="${wheel_off_x}"/>
  <xacro:wheel prefix="rear_left"   reflect_y="1"  x_offset="-${wheel_off_x}"/>
  <xacro:wheel prefix="rear_right"  reflect_y="-1" x_offset="-${wheel_off_x}"/>

  <link name="standoff_link">
    <visual>
      <origin xyz="0 0 0" rpy="0 0 0"/>
      <geometry>
        <cylinder radius="0.005" length="${standoff_height}"/>
      </geometry>
      <material name="gold"/>
    </visual>
  </link>

  <joint name="standoff_joint" type="fixed">
    <parent link="base_link"/>
    <child link="standoff_link"/>
    <origin xyz="${lidar_off_x} 0 ${base_height/2 + standoff_height/2}" rpy="0 0 0"/>
  </joint>

  <link name="laser">
    <visual>
      <origin xyz="0 0 0" rpy="0 0 0"/>
      <geometry>
        <cylinder radius="${lidar_radius}" length="${lidar_height}"/>
      </geometry>
      <material name="black"/>
    </visual>
  </link>

  <joint name="laser_joint" type="fixed">
    <parent link="base_link"/>
    <child link="laser"/>
    <origin xyz="${lidar_off_x} 0 ${base_height/2 + standoff_height + lidar_height/2}" rpy="0 0 0"/>
  </joint>
  
  <gazebo>
        <plugin
            filename="gz-sim-diff-drive-system"
            name="gz::sim::systems::DiffDrive">
            <left_joint>left_wheel_joint</left_joint>
            <right_joint>right_wheel_joint</right_joint>
            <wheel_separation>0.2</wheel_separation>
            <wheel_radius>0.0325</wheel_radius>
            <odom_publish_frequency>1</odom_publish_frequency>
            <topic>cmd_vel</topic>
            <odom_topic>odom</odom_topic>
            <tf_topic>tf</tf_topic>
            <frame_id>odom</frame_id>
            <child_frame_id>base_link</child_frame_id>
        </plugin>

        <plugin
            filename="gz-sim-sensors-system"
            name="gz::sim::systems::Sensors">
            <render_engine>ogre2</render_engine>
        </plugin>
    </gazebo>

    <gazebo reference="camera_link">
        <sensor name="camera" type="camera">
            <topic>camera/image_raw</topic> <update_rate>10</update_rate>
            <camera>
                <horizontal_fov>1.089</horizontal_fov>
                <image>
                    <width>640</width>
                    <height>480</height>
                    <format>R8G8B8</format>
                </image>
                <clip>
                    <near>0.05</near>
                    <far>8.0</far>
                </clip>
            </camera>
            <always_on>1</always_on>
            <visualize>true</visualize>
        </sensor>
    </gazebo>
</robot>
